[0m15:08:31.938199 [debug] [MainThread]: Sending event: {'category': 'dbt', 'action': 'invocation', 'label': 'start', 'context': [<snowplow_tracker.self_describing_json.SelfDescribingJson object at 0x768db7709cd0>, <snowplow_tracker.self_describing_json.SelfDescribingJson object at 0x768db7e3d9a0>, <snowplow_tracker.self_describing_json.SelfDescribingJson object at 0x768db7e3fbf0>]}


============================== 15:08:31.942524 | 79753f2d-9a74-406a-afd3-257d6132acea ==============================
[0m15:08:31.942524 [info ] [MainThread]: Running with dbt=1.9.4
[0m15:08:31.942993 [debug] [MainThread]: running dbt with arguments {'printer_width': '80', 'indirect_selection': 'eager', 'write_json': 'True', 'log_cache_events': 'False', 'partial_parse': 'True', 'cache_selected_only': 'False', 'warn_error': 'None', 'debug': 'False', 'fail_fast': 'False', 'log_path': 'logs', 'profiles_dir': '/home/lite/.dbt', 'version_check': 'True', 'use_colors': 'True', 'use_experimental_parser': 'False', 'empty': 'None', 'quiet': 'False', 'no_print': 'None', 'log_format': 'default', 'introspect': 'True', 'static_parser': 'True', 'invocation_command': 'dbt init', 'target_path': 'None', 'warn_error_options': 'WarnErrorOptions(include=[], exclude=[])', 'send_anonymous_usage_stats': 'True'}
[0m16:20:18.938620 [debug] [MainThread]: Starter project path: /home/lite/dbt_workspace/venv/lib/python3.12/site-packages/dbt/include/starter_project
[0m16:20:18.946987 [info ] [MainThread]: 
Your new dbt project "dbt_proj" was created!

For more information on how to configure the profiles.yml file,
please consult the dbt documentation here:

  https://docs.getdbt.com/docs/configure-your-profile

One more thing:

Need help? Don't hesitate to reach out to us via GitHub issues or on Slack:

  https://community.getdbt.com/

Happy modeling!

[0m16:20:18.947592 [info ] [MainThread]: Setting up your profile.
[0m16:20:18.950449 [error] [MainThread]: Encountered an error:
while parsing a block mapping
  in "/home/lite/.dbt/profiles.yml", line 3, column 3
expected <block end>, but found '<block mapping start>'
  in "/home/lite/.dbt/profiles.yml", line 15, column 5
[0m16:20:18.954412 [error] [MainThread]: Traceback (most recent call last):
  File "/home/lite/dbt_workspace/venv/lib/python3.12/site-packages/dbt/cli/requires.py", line 153, in wrapper
    result, success = func(*args, **kwargs)
                      ^^^^^^^^^^^^^^^^^^^^^
  File "/home/lite/dbt_workspace/venv/lib/python3.12/site-packages/dbt/cli/requires.py", line 103, in wrapper
    return func(*args, **kwargs)
           ^^^^^^^^^^^^^^^^^^^^^
  File "/home/lite/dbt_workspace/venv/lib/python3.12/site-packages/dbt/cli/main.py", line 477, in init
    results = task.run()
              ^^^^^^^^^^
  File "/home/lite/dbt_workspace/venv/lib/python3.12/site-packages/dbt/task/init.py", line 346, in run
    self.setup_profile(profile_name)
  File "/home/lite/dbt_workspace/venv/lib/python3.12/site-packages/dbt/task/init.py", line 248, in setup_profile
    if not self.check_if_can_write_profile(profile_name=profile_name):
           ^^^^^^^^^^^^^^^^^^^^^^^^^^^^^^^^^^^^^^^^^^^^^^^^^^^^^^^^^^
  File "/home/lite/dbt_workspace/venv/lib/python3.12/site-packages/dbt/task/init.py", line 209, in check_if_can_write_profile
    profiles = yaml.safe_load(f) or {}
               ^^^^^^^^^^^^^^^^^
  File "/home/lite/dbt_workspace/venv/lib/python3.12/site-packages/yaml/__init__.py", line 125, in safe_load
    return load(stream, SafeLoader)
           ^^^^^^^^^^^^^^^^^^^^^^^^
  File "/home/lite/dbt_workspace/venv/lib/python3.12/site-packages/yaml/__init__.py", line 81, in load
    return loader.get_single_data()
           ^^^^^^^^^^^^^^^^^^^^^^^^
  File "/home/lite/dbt_workspace/venv/lib/python3.12/site-packages/yaml/constructor.py", line 49, in get_single_data
    node = self.get_single_node()
           ^^^^^^^^^^^^^^^^^^^^^^
  File "/home/lite/dbt_workspace/venv/lib/python3.12/site-packages/yaml/composer.py", line 36, in get_single_node
    document = self.compose_document()
               ^^^^^^^^^^^^^^^^^^^^^^^
  File "/home/lite/dbt_workspace/venv/lib/python3.12/site-packages/yaml/composer.py", line 55, in compose_document
    node = self.compose_node(None, None)
           ^^^^^^^^^^^^^^^^^^^^^^^^^^^^^
  File "/home/lite/dbt_workspace/venv/lib/python3.12/site-packages/yaml/composer.py", line 84, in compose_node
    node = self.compose_mapping_node(anchor)
           ^^^^^^^^^^^^^^^^^^^^^^^^^^^^^^^^^
  File "/home/lite/dbt_workspace/venv/lib/python3.12/site-packages/yaml/composer.py", line 133, in compose_mapping_node
    item_value = self.compose_node(node, item_key)
                 ^^^^^^^^^^^^^^^^^^^^^^^^^^^^^^^^^
  File "/home/lite/dbt_workspace/venv/lib/python3.12/site-packages/yaml/composer.py", line 84, in compose_node
    node = self.compose_mapping_node(anchor)
           ^^^^^^^^^^^^^^^^^^^^^^^^^^^^^^^^^
  File "/home/lite/dbt_workspace/venv/lib/python3.12/site-packages/yaml/composer.py", line 127, in compose_mapping_node
    while not self.check_event(MappingEndEvent):
              ^^^^^^^^^^^^^^^^^^^^^^^^^^^^^^^^^
  File "/home/lite/dbt_workspace/venv/lib/python3.12/site-packages/yaml/parser.py", line 98, in check_event
    self.current_event = self.state()
                         ^^^^^^^^^^^^
  File "/home/lite/dbt_workspace/venv/lib/python3.12/site-packages/yaml/parser.py", line 438, in parse_block_mapping_key
    raise ParserError("while parsing a block mapping", self.marks[-1],
yaml.parser.ParserError: while parsing a block mapping
  in "/home/lite/.dbt/profiles.yml", line 3, column 3
expected <block end>, but found '<block mapping start>'
  in "/home/lite/.dbt/profiles.yml", line 15, column 5

[0m16:20:18.957110 [debug] [MainThread]: Resource report: {"command_name": "init", "command_success": false, "command_wall_clock_time": 4307.025, "process_in_blocks": "1648", "process_kernel_time": 0.145958, "process_mem_max_rss": "94516", "process_out_blocks": "80", "process_user_time": 1.070365}
[0m16:20:18.957810 [debug] [MainThread]: Command `dbt init` failed at 16:20:18.957634 after 4307.03 seconds
[0m16:20:18.958716 [debug] [MainThread]: Sending event: {'category': 'dbt', 'action': 'invocation', 'label': 'end', 'context': [<snowplow_tracker.self_describing_json.SelfDescribingJson object at 0x768db7709e50>, <snowplow_tracker.self_describing_json.SelfDescribingJson object at 0x768db7815340>, <snowplow_tracker.self_describing_json.SelfDescribingJson object at 0x768db77acda0>]}
[0m16:20:18.959348 [debug] [MainThread]: Flushing usage events
[0m16:20:19.723051 [debug] [MainThread]: An error was encountered while trying to flush usage events
[0m13:56:14.215416 [debug] [MainThread]: Sending event: {'category': 'dbt', 'action': 'invocation', 'label': 'start', 'context': [<snowplow_tracker.self_describing_json.SelfDescribingJson object at 0x7c3e440fd7c0>, <snowplow_tracker.self_describing_json.SelfDescribingJson object at 0x7c3e44725a00>, <snowplow_tracker.self_describing_json.SelfDescribingJson object at 0x7c3e440fd820>]}


============================== 13:56:14.222165 | 583db5d0-2cf7-4094-ad4f-c3ae1ca5f215 ==============================
[0m13:56:14.222165 [info ] [MainThread]: Running with dbt=1.9.4
[0m13:56:14.223117 [debug] [MainThread]: running dbt with arguments {'printer_width': '80', 'indirect_selection': 'eager', 'log_cache_events': 'False', 'write_json': 'True', 'partial_parse': 'True', 'cache_selected_only': 'False', 'warn_error': 'None', 'version_check': 'True', 'fail_fast': 'False', 'log_path': 'logs', 'profiles_dir': '/home/lite/.dbt', 'debug': 'False', 'use_colors': 'True', 'use_experimental_parser': 'False', 'no_print': 'None', 'quiet': 'False', 'empty': 'None', 'warn_error_options': 'WarnErrorOptions(include=[], exclude=[])', 'invocation_command': 'dbt debug', 'static_parser': 'True', 'log_format': 'default', 'target_path': 'None', 'introspect': 'True', 'send_anonymous_usage_stats': 'True'}
[0m13:56:14.234930 [info ] [MainThread]: dbt version: 1.9.4
[0m13:56:14.235503 [info ] [MainThread]: python version: 3.12.3
[0m13:56:14.236045 [info ] [MainThread]: python path: /home/lite/dbt_workspace/.venv/bin/python
[0m13:56:14.236355 [info ] [MainThread]: os info: Linux-6.8.0-57-generic-x86_64-with-glibc2.39
[0m13:56:14.237238 [error] [MainThread]: Encountered an error:
Runtime Error
  Syntax error near line 15
  ------------------------------
  12 | 
  13 | 
  14 |     # Snowflake iÃ§in Ã§Ä±kÄ±ÅŸ yapÄ±landÄ±rmasÄ±
  15 |     snowflake_target:
  16 |       type: snowflake
  17 |       account: eu-central-2.aws/ki21889        # Snowflake hesap adÄ± (Ã¶r. xy12345.east-us-2.azure)
  18 |       user: ELIF              # Snowflake kullanÄ±cÄ± adÄ±
  
  Raw Error:
  ------------------------------
  while parsing a block mapping
    in "<unicode string>", line 3, column 3
  did not find expected key
    in "<unicode string>", line 15, column 5
[0m13:56:14.238471 [debug] [MainThread]: Resource report: {"command_name": "debug", "command_success": false, "command_wall_clock_time": 0.031243226, "process_in_blocks": "0", "process_kernel_time": 0.200673, "process_mem_max_rss": "94148", "process_out_blocks": "16", "process_user_time": 1.847508}
[0m13:56:14.239192 [debug] [MainThread]: Command `dbt debug` failed at 13:56:14.239066 after 0.03 seconds
[0m13:56:14.240191 [debug] [MainThread]: Sending event: {'category': 'dbt', 'action': 'invocation', 'label': 'end', 'context': [<snowplow_tracker.self_describing_json.SelfDescribingJson object at 0x7c3e4412c200>, <snowplow_tracker.self_describing_json.SelfDescribingJson object at 0x7c3e4412c170>, <snowplow_tracker.self_describing_json.SelfDescribingJson object at 0x7c3e440fdb80>]}
[0m13:56:14.240930 [debug] [MainThread]: Flushing usage events
[0m13:56:14.831370 [debug] [MainThread]: An error was encountered while trying to flush usage events
[0m13:56:20.681005 [debug] [MainThread]: Sending event: {'category': 'dbt', 'action': 'invocation', 'label': 'start', 'context': [<snowplow_tracker.self_describing_json.SelfDescribingJson object at 0x7e26db211a00>, <snowplow_tracker.self_describing_json.SelfDescribingJson object at 0x7e26db211d60>, <snowplow_tracker.self_describing_json.SelfDescribingJson object at 0x7e26db211b50>]}


============================== 13:56:20.685505 | 05d1dfbf-70f1-4f74-9584-b268021e0196 ==============================
[0m13:56:20.685505 [info ] [MainThread]: Running with dbt=1.9.4
[0m13:56:20.686352 [debug] [MainThread]: running dbt with arguments {'printer_width': '80', 'indirect_selection': 'eager', 'write_json': 'True', 'log_cache_events': 'False', 'partial_parse': 'True', 'cache_selected_only': 'False', 'profiles_dir': '/home/lite/.dbt', 'fail_fast': 'False', 'version_check': 'True', 'log_path': 'logs', 'warn_error': 'None', 'debug': 'False', 'use_colors': 'True', 'use_experimental_parser': 'False', 'no_print': 'None', 'quiet': 'False', 'empty': 'False', 'warn_error_options': 'WarnErrorOptions(include=[], exclude=[])', 'invocation_command': 'dbt run', 'static_parser': 'True', 'introspect': 'True', 'target_path': 'None', 'log_format': 'default', 'send_anonymous_usage_stats': 'True'}
[0m13:56:20.687152 [error] [MainThread]: Encountered an error:
Runtime Error
  No dbt_project.yml found at expected path /home/lite/dbt_workspace/dbt_project.yml
  Verify that each entry within packages.yml (and their transitive dependencies) contains a file named dbt_project.yml
  
[0m13:56:20.688312 [debug] [MainThread]: Resource report: {"command_name": "run", "command_success": false, "command_wall_clock_time": 0.012690088, "process_in_blocks": "0", "process_kernel_time": 0.156472, "process_mem_max_rss": "92176", "process_out_blocks": "0", "process_user_time": 1.542516}
[0m13:56:20.689107 [debug] [MainThread]: Command `dbt run` failed at 13:56:20.688949 after 0.01 seconds
[0m13:56:20.689710 [debug] [MainThread]: Sending event: {'category': 'dbt', 'action': 'invocation', 'label': 'end', 'context': [<snowplow_tracker.self_describing_json.SelfDescribingJson object at 0x7e26dfb0f8c0>, <snowplow_tracker.self_describing_json.SelfDescribingJson object at 0x7e26dd7f8f80>, <snowplow_tracker.self_describing_json.SelfDescribingJson object at 0x7e26db395460>]}
[0m13:56:20.690190 [debug] [MainThread]: Flushing usage events
[0m13:56:21.303335 [debug] [MainThread]: An error was encountered while trying to flush usage events
[0m14:00:41.177517 [debug] [MainThread]: Sending event: {'category': 'dbt', 'action': 'invocation', 'label': 'start', 'context': [<snowplow_tracker.self_describing_json.SelfDescribingJson object at 0x79853a757440>, <snowplow_tracker.self_describing_json.SelfDescribingJson object at 0x79853a920440>, <snowplow_tracker.self_describing_json.SelfDescribingJson object at 0x79853a899e80>]}


============================== 14:00:41.183189 | b1b206c6-c021-428f-a89a-4b34aa3899f0 ==============================
[0m14:00:41.183189 [info ] [MainThread]: Running with dbt=1.9.4
[0m14:00:41.184035 [debug] [MainThread]: running dbt with arguments {'printer_width': '80', 'indirect_selection': 'eager', 'write_json': 'True', 'log_cache_events': 'False', 'partial_parse': 'True', 'cache_selected_only': 'False', 'warn_error': 'None', 'version_check': 'True', 'profiles_dir': '/home/lite/.dbt', 'log_path': 'logs', 'fail_fast': 'False', 'debug': 'False', 'use_colors': 'True', 'use_experimental_parser': 'False', 'empty': 'None', 'quiet': 'False', 'no_print': 'None', 'log_format': 'default', 'invocation_command': 'dbt debug', 'warn_error_options': 'WarnErrorOptions(include=[], exclude=[])', 'static_parser': 'True', 'target_path': 'None', 'introspect': 'True', 'send_anonymous_usage_stats': 'True'}
[0m14:00:41.202813 [info ] [MainThread]: dbt version: 1.9.4
[0m14:00:41.205709 [info ] [MainThread]: python version: 3.12.3
[0m14:00:41.206520 [info ] [MainThread]: python path: /home/lite/dbt_workspace/.venv/bin/python
[0m14:00:41.209213 [info ] [MainThread]: os info: Linux-6.8.0-57-generic-x86_64-with-glibc2.39
[0m14:00:41.210738 [info ] [MainThread]: target not specified in profile 'name', using 'default'
[0m14:00:41.211892 [info ] [MainThread]: target not specified in profile 'version', using 'default'
[0m14:00:41.212723 [info ] [MainThread]: target not specified in profile 'profile', using 'default'
[0m14:00:41.213489 [info ] [MainThread]: target not specified in profile 'model-paths', using 'default'
[0m14:00:41.214016 [info ] [MainThread]: target not specified in profile 'analysis-paths', using 'default'
[0m14:00:41.214933 [info ] [MainThread]: target not specified in profile 'test-paths', using 'default'
[0m14:00:41.215612 [info ] [MainThread]: target not specified in profile 'seed-paths', using 'default'
[0m14:00:41.216454 [info ] [MainThread]: target not specified in profile 'macro-paths', using 'default'
[0m14:00:41.217076 [info ] [MainThread]: target not specified in profile 'snapshot-paths', using 'default'
[0m14:00:41.217862 [error] [MainThread]: Encountered an error:
list indices must be integers or slices, not str
[0m14:00:41.219626 [error] [MainThread]: Traceback (most recent call last):
  File "/home/lite/dbt_workspace/.venv/lib/python3.12/site-packages/dbt/cli/requires.py", line 153, in wrapper
    result, success = func(*args, **kwargs)
                      ^^^^^^^^^^^^^^^^^^^^^
  File "/home/lite/dbt_workspace/.venv/lib/python3.12/site-packages/dbt/cli/requires.py", line 103, in wrapper
    return func(*args, **kwargs)
           ^^^^^^^^^^^^^^^^^^^^^
  File "/home/lite/dbt_workspace/.venv/lib/python3.12/site-packages/dbt/cli/main.py", line 414, in debug
    results = task.run()
              ^^^^^^^^^^
  File "/home/lite/dbt_workspace/.venv/lib/python3.12/site-packages/dbt/task/debug.py", line 114, in run
    load_profile_status: SubtaskStatus = self._load_profile()
                                         ^^^^^^^^^^^^^^^^^^^^
  File "/home/lite/dbt_workspace/.venv/lib/python3.12/site-packages/dbt/task/debug.py", line 205, in _load_profile
    profile: Profile = Profile.render(
                       ^^^^^^^^^^^^^^^
  File "/home/lite/dbt_workspace/.venv/lib/python3.12/site-packages/dbt/config/profile.py", line 402, in render
    return cls.from_raw_profiles(
           ^^^^^^^^^^^^^^^^^^^^^^
  File "/home/lite/dbt_workspace/.venv/lib/python3.12/site-packages/dbt/config/profile.py", line 368, in from_raw_profiles
    return cls.from_raw_profile_info(
           ^^^^^^^^^^^^^^^^^^^^^^^^^^
  File "/home/lite/dbt_workspace/.venv/lib/python3.12/site-packages/dbt/config/profile.py", line 314, in from_raw_profile_info
    target_name, profile_data = cls.render_profile(
                                ^^^^^^^^^^^^^^^^^^^
  File "/home/lite/dbt_workspace/.venv/lib/python3.12/site-packages/dbt/config/profile.py", line 275, in render_profile
    target_name = renderer.render_value(raw_profile["target"])
                                        ~~~~~~~~~~~^^^^^^^^^^
TypeError: list indices must be integers or slices, not str

[0m14:00:41.222432 [debug] [MainThread]: Resource report: {"command_name": "debug", "command_success": false, "command_wall_clock_time": 0.08582583, "process_in_blocks": "0", "process_kernel_time": 0.527713, "process_mem_max_rss": "95220", "process_out_blocks": "16", "process_user_time": 0.930517}
[0m14:00:41.223039 [debug] [MainThread]: Command `dbt debug` failed at 14:00:41.222913 after 0.09 seconds
[0m14:00:41.223448 [debug] [MainThread]: Sending event: {'category': 'dbt', 'action': 'invocation', 'label': 'end', 'context': [<snowplow_tracker.self_describing_json.SelfDescribingJson object at 0x79853a920440>, <snowplow_tracker.self_describing_json.SelfDescribingJson object at 0x79853a899e80>, <snowplow_tracker.self_describing_json.SelfDescribingJson object at 0x798539caadb0>]}
[0m14:00:41.224145 [debug] [MainThread]: Flushing usage events
[0m14:00:41.979302 [debug] [MainThread]: An error was encountered while trying to flush usage events
[0m14:00:51.057057 [debug] [MainThread]: Sending event: {'category': 'dbt', 'action': 'invocation', 'label': 'start', 'context': [<snowplow_tracker.self_describing_json.SelfDescribingJson object at 0x7c2ab464dbe0>, <snowplow_tracker.self_describing_json.SelfDescribingJson object at 0x7c2ab2a28b90>, <snowplow_tracker.self_describing_json.SelfDescribingJson object at 0x7c2ab2a28bf0>]}


============================== 14:00:51.060272 | 3d0fe6db-5711-43c7-99b3-4862ddf57a48 ==============================
[0m14:00:51.060272 [info ] [MainThread]: Running with dbt=1.9.4
[0m14:00:51.061079 [debug] [MainThread]: running dbt with arguments {'printer_width': '80', 'indirect_selection': 'eager', 'log_cache_events': 'False', 'write_json': 'True', 'partial_parse': 'True', 'cache_selected_only': 'False', 'warn_error': 'None', 'version_check': 'True', 'fail_fast': 'False', 'log_path': 'logs', 'debug': 'False', 'profiles_dir': '/home/lite/.dbt', 'use_colors': 'True', 'use_experimental_parser': 'False', 'no_print': 'None', 'quiet': 'False', 'empty': 'False', 'log_format': 'default', 'static_parser': 'True', 'invocation_command': 'dbt run', 'warn_error_options': 'WarnErrorOptions(include=[], exclude=[])', 'target_path': 'None', 'introspect': 'True', 'send_anonymous_usage_stats': 'True'}
[0m14:00:51.061640 [error] [MainThread]: Encountered an error:
Runtime Error
  No dbt_project.yml found at expected path /home/lite/dbt_workspace/dbt_project.yml
  Verify that each entry within packages.yml (and their transitive dependencies) contains a file named dbt_project.yml
  
[0m14:00:51.062740 [debug] [MainThread]: Resource report: {"command_name": "run", "command_success": false, "command_wall_clock_time": 0.06318511, "process_in_blocks": "0", "process_kernel_time": 0.185019, "process_mem_max_rss": "93420", "process_out_blocks": "8", "process_user_time": 1.742012}
[0m14:00:51.063197 [debug] [MainThread]: Command `dbt run` failed at 14:00:51.063104 after 0.06 seconds
[0m14:00:51.063741 [debug] [MainThread]: Sending event: {'category': 'dbt', 'action': 'invocation', 'label': 'end', 'context': [<snowplow_tracker.self_describing_json.SelfDescribingJson object at 0x7c2ab2b96ab0>, <snowplow_tracker.self_describing_json.SelfDescribingJson object at 0x7c2ab2444380>, <snowplow_tracker.self_describing_json.SelfDescribingJson object at 0x7c2ab464dbe0>]}
[0m14:00:51.064133 [debug] [MainThread]: Flushing usage events
[0m14:00:51.728025 [debug] [MainThread]: An error was encountered while trying to flush usage events
